[2022-07-16 07:11:14,043] {taskinstance.py:1032} INFO - Dependencies all met for <TaskInstance: gh_data_ingestion.bq_gh_external_table_task scheduled__2022-07-14T02:30:00+00:00 [queued]>
[2022-07-16 07:11:14,096] {taskinstance.py:1032} INFO - Dependencies all met for <TaskInstance: gh_data_ingestion.bq_gh_external_table_task scheduled__2022-07-14T02:30:00+00:00 [queued]>
[2022-07-16 07:11:14,098] {taskinstance.py:1238} INFO - 
--------------------------------------------------------------------------------
[2022-07-16 07:11:14,100] {taskinstance.py:1239} INFO - Starting attempt 1 of 2
[2022-07-16 07:11:14,102] {taskinstance.py:1240} INFO - 
--------------------------------------------------------------------------------
[2022-07-16 07:11:14,140] {taskinstance.py:1259} INFO - Executing <Task(BigQueryCreateExternalTableOperator): bq_gh_external_table_task> on 2022-07-14 02:30:00+00:00
[2022-07-16 07:11:14,154] {standard_task_runner.py:52} INFO - Started process 363 to run task
[2022-07-16 07:11:14,176] {standard_task_runner.py:76} INFO - Running: ['***', 'tasks', 'run', 'gh_data_ingestion', 'bq_gh_external_table_task', 'scheduled__2022-07-14T02:30:00+00:00', '--job-id', '10', '--raw', '--subdir', 'DAGS_FOLDER/data_ingestion_gh.py', '--cfg-path', '/tmp/tmp5qcay_rz', '--error-file', '/tmp/tmpdtlcutmw']
[2022-07-16 07:11:14,181] {standard_task_runner.py:77} INFO - Job 10: Subtask bq_gh_external_table_task
[2022-07-16 07:11:14,397] {logging_mixin.py:109} INFO - Running <TaskInstance: gh_data_ingestion.bq_gh_external_table_task scheduled__2022-07-14T02:30:00+00:00 [running]> on host 4972e04a2617
[2022-07-16 07:11:15,010] {taskinstance.py:1426} INFO - Exporting the following env vars:
AIRFLOW_CTX_DAG_OWNER=***
AIRFLOW_CTX_DAG_ID=gh_data_ingestion
AIRFLOW_CTX_TASK_ID=bq_gh_external_table_task
AIRFLOW_CTX_EXECUTION_DATE=2022-07-14T02:30:00+00:00
AIRFLOW_CTX_DAG_RUN_ID=scheduled__2022-07-14T02:30:00+00:00
[2022-07-16 07:11:15,033] {crypto.py:82} WARNING - empty cryptography key - values will not be stored encrypted.
[2022-07-16 07:11:16,468] {taskinstance.py:1700} ERROR - Task failed with exception
Traceback (most recent call last):
  File "/home/airflow/.local/lib/python3.7/site-packages/airflow/models/taskinstance.py", line 1329, in _run_raw_task
    self._execute_task_with_callbacks(context)
  File "/home/airflow/.local/lib/python3.7/site-packages/airflow/models/taskinstance.py", line 1455, in _execute_task_with_callbacks
    result = self._execute_task(context, self.task)
  File "/home/airflow/.local/lib/python3.7/site-packages/airflow/models/taskinstance.py", line 1511, in _execute_task
    result = execute_callable(context=context)
  File "/home/airflow/.local/lib/python3.7/site-packages/airflow/providers/google/cloud/operators/bigquery.py", line 1196, in execute
    table_resource=self.table_resource,
  File "/home/airflow/.local/lib/python3.7/site-packages/airflow/providers/google/common/hooks/base_google.py", line 430, in inner_wrapper
    return func(self, *args, **kwargs)
  File "/home/airflow/.local/lib/python3.7/site-packages/airflow/providers/google/cloud/hooks/bigquery.py", line 408, in create_empty_table
    table=table, exists_ok=exists_ok, retry=retry
  File "/home/airflow/.local/lib/python3.7/site-packages/google/cloud/bigquery/client.py", line 755, in create_table
    timeout=timeout,
  File "/home/airflow/.local/lib/python3.7/site-packages/google/cloud/bigquery/client.py", line 782, in _call_api
    return call()
  File "/home/airflow/.local/lib/python3.7/site-packages/google/api_core/retry.py", line 291, in retry_wrapped_func
    on_error=on_error,
  File "/home/airflow/.local/lib/python3.7/site-packages/google/api_core/retry.py", line 189, in retry_target
    return target()
  File "/home/airflow/.local/lib/python3.7/site-packages/google/cloud/_http.py", line 484, in api_request
    raise exceptions.from_http_response(response)
google.api_core.exceptions.NotFound: 404 POST https://bigquery.googleapis.com/bigquery/v2/projects/dtc-de-course-351511/datasets/gh_archive_all/tables?prettyPrint=false: Not found: Dataset dtc-de-course-351511:gh_archive_all
[2022-07-16 07:11:16,532] {taskinstance.py:1277} INFO - Marking task as UP_FOR_RETRY. dag_id=gh_data_ingestion, task_id=bq_gh_external_table_task, execution_date=20220714T023000, start_date=20220716T071114, end_date=20220716T071116
[2022-07-16 07:11:16,595] {standard_task_runner.py:92} ERROR - Failed to execute job 10 for task bq_gh_external_table_task
Traceback (most recent call last):
  File "/home/airflow/.local/lib/python3.7/site-packages/airflow/task/task_runner/standard_task_runner.py", line 85, in _start_by_fork
    args.func(args, dag=self.dag)
  File "/home/airflow/.local/lib/python3.7/site-packages/airflow/cli/cli_parser.py", line 48, in command
    return func(*args, **kwargs)
  File "/home/airflow/.local/lib/python3.7/site-packages/airflow/utils/cli.py", line 92, in wrapper
    return f(*args, **kwargs)
  File "/home/airflow/.local/lib/python3.7/site-packages/airflow/cli/commands/task_command.py", line 298, in task_run
    _run_task_by_selected_method(args, dag, ti)
  File "/home/airflow/.local/lib/python3.7/site-packages/airflow/cli/commands/task_command.py", line 107, in _run_task_by_selected_method
    _run_raw_task(args, ti)
  File "/home/airflow/.local/lib/python3.7/site-packages/airflow/cli/commands/task_command.py", line 184, in _run_raw_task
    error_file=args.error_file,
  File "/home/airflow/.local/lib/python3.7/site-packages/airflow/utils/session.py", line 70, in wrapper
    return func(*args, session=session, **kwargs)
  File "/home/airflow/.local/lib/python3.7/site-packages/airflow/models/taskinstance.py", line 1329, in _run_raw_task
    self._execute_task_with_callbacks(context)
  File "/home/airflow/.local/lib/python3.7/site-packages/airflow/models/taskinstance.py", line 1455, in _execute_task_with_callbacks
    result = self._execute_task(context, self.task)
  File "/home/airflow/.local/lib/python3.7/site-packages/airflow/models/taskinstance.py", line 1511, in _execute_task
    result = execute_callable(context=context)
  File "/home/airflow/.local/lib/python3.7/site-packages/airflow/providers/google/cloud/operators/bigquery.py", line 1196, in execute
    table_resource=self.table_resource,
  File "/home/airflow/.local/lib/python3.7/site-packages/airflow/providers/google/common/hooks/base_google.py", line 430, in inner_wrapper
    return func(self, *args, **kwargs)
  File "/home/airflow/.local/lib/python3.7/site-packages/airflow/providers/google/cloud/hooks/bigquery.py", line 408, in create_empty_table
    table=table, exists_ok=exists_ok, retry=retry
  File "/home/airflow/.local/lib/python3.7/site-packages/google/cloud/bigquery/client.py", line 755, in create_table
    timeout=timeout,
  File "/home/airflow/.local/lib/python3.7/site-packages/google/cloud/bigquery/client.py", line 782, in _call_api
    return call()
  File "/home/airflow/.local/lib/python3.7/site-packages/google/api_core/retry.py", line 291, in retry_wrapped_func
    on_error=on_error,
  File "/home/airflow/.local/lib/python3.7/site-packages/google/api_core/retry.py", line 189, in retry_target
    return target()
  File "/home/airflow/.local/lib/python3.7/site-packages/google/cloud/_http.py", line 484, in api_request
    raise exceptions.from_http_response(response)
google.api_core.exceptions.NotFound: 404 POST https://bigquery.googleapis.com/bigquery/v2/projects/dtc-de-course-351511/datasets/gh_archive_all/tables?prettyPrint=false: Not found: Dataset dtc-de-course-351511:gh_archive_all
[2022-07-16 07:11:16,620] {local_task_job.py:154} INFO - Task exited with return code 1
[2022-07-16 07:11:16,716] {local_task_job.py:264} INFO - 0 downstream tasks scheduled from follow-on schedule check
